Workbook

Sheet Data
A1: Full Name | B1: Job Title | C1: Company Name | D1: Experience | E1: Skills 1 | F1: Skills 2 | G1: linkedinPublicUrl | H1: city | I1: state | J1: country | L1: Email
A2: SanjaiReddi BE,ME(D) | B2: CHIEF EXECUTIVE | D2: 14+ | E2: Account Management | F2: Data Analysis | G2: https://www.linkedin.com/in/sanjaireddi-be-me-d-098bb84b | H2: Coimbatore | I2: India | J2: India | L2: =IFERROR(_xlfn.XLOOKUP(TRIM(G2), Sheet1!$C:$C, Sheet1!$E:$E), "")
A3: Henry Wald | B3: Engineer | C3: Specsys Inc. | D3: 4+ | E3: Troubleshooting | F3: Mechanical Engineering | G3: https://www.linkedin.com/in/henry-wald-07b4551a1 | H3: Minneapolis | I3: United Kingdom | J3: United States | L3: =IFERROR(_xlfn.XLOOKUP(TRIM(G3), Sheet1!$C:$C, Sheet1!$E:$E), "")
A4: Saket Sankhla | B4: Business Process Transformation Leader | C4: Schneider Electric | D4: 1+ | E4: Manufacturing Process Improvement | F4: Legacy Modernization | G4: https://www.linkedin.com/in/saket-sankhla | H4: Boston | I4: Oman | J4: United States | L4: =IFERROR(_xlfn.XLOOKUP(TRIM(G4), Sheet1!$C:$C, Sheet1!$E:$E), "")
A5: BRAGADEESH V | B5: Ex-Application Development Intern | C5: Citi India | D5: 0.7 | E5: Problem Solving | F5: Databases | G5: https://www.linkedin.com/in/bragadeesh05 | H5: Tiruppur | I5: India | J5: India | L5: =IFERROR(_xlfn.XLOOKUP(TRIM(G5), Sheet1!$C:$C, Sheet1!$E:$E), "")
A6: Akshama Panwar | B6: Team Lead | D6: 4+ | G6: https://www.linkedin.com/in/akshama-panwar-580b2a70 | H6: Randolph | I6: Canada | J6: United States | L6: =IFERROR(_xlfn.XLOOKUP(TRIM(G6), Sheet1!$C:$C, Sheet1!$E:$E), "")
A7: Shakthi S. Shanmugam | B7: Paid Media Manager | C7: Klatch | D7: 0.2 | E7: Interpersonal Skills | F7: Attention to Detail | G7: https://www.linkedin.com/in/sakthivelshanmugam | H7: Brighton | I7: Qatar | J7: United Kingdom | L7: =IFERROR(_xlfn.XLOOKUP(TRIM(G7), Sheet1!$C:$C, Sheet1!$E:$E), "")
A8: Arun Raj k | B8: HR Executive | C8: Crux Prestressing Systems | D8: 2 | E8: Recruiting | F8: Information Technology | G8: https://www.linkedin.com/in/arun-raj-k-890274193 | H8: Hyderabad | I8: Saudi Arabia | J8: India | L8: =IFERROR(_xlfn.XLOOKUP(TRIM(G8), Sheet1!$C:$C, Sheet1!$E:$E), "")
A9: Anjali Balakrishnan | B9: Regional Strategy Manager | C9: Signify Health | D9: 1 | E9: Due Diligence | F9: Financial Modeling | G9: https://www.linkedin.com/in/anjali-balakrishnan-3b971217a | H9: Chicago | I9: Indonesia | J9: United States | L9: =IFERROR(_xlfn.XLOOKUP(TRIM(G9), Sheet1!$C:$C, Sheet1!$E:$E), "")
A10: Rogel D. | B10: Data Migration Specialist | C10: Global Relay | D10: 3+ | E10: Administrative Assistance | F10: Problem Solving | G10: https://www.linkedin.com/in/rogel-d-4b182548 | H10: Vancouver | I10: Germany | J10: Canada | L10: =IFERROR(_xlfn.XLOOKUP(TRIM(G10), Sheet1!$C:$C, Sheet1!$E:$E), "")
A11: Vignesh GS | B11: Consulting Partner | C11: Era Group - North America | D11: 2+ | E11: Sales | F11: Product Operations | G11: https://www.linkedin.com/in/gsvignesh | H11: Atlanta | I11: United States | J11: United States | L11: =IFERROR(_xlfn.XLOOKUP(TRIM(G11), Sheet1!$C:$C, Sheet1!$E:$E), "")
A12: Angeline Benjamin | B12: Action Coach with Results | D12: 9+ | E12: Food Safety | F12: Food | G12: https://www.linkedin.com/in/angelinebenjamin | H12: Queen Creek | I12: California | J12: United States | L12: =IFERROR(_xlfn.XLOOKUP(TRIM(G12), Sheet1!$C:$C, Sheet1!$E:$E), "")
A13: Varnell Smith | B13: Senior Talent Acquisition Professional | D13: 11+ | E13: Human Resources | F13: Temporary Placement | G13: https://www.linkedin.com/in/varnell-smith-9702935 | H13: N/A | I13: N/A | J13: N/A | L13: =IFERROR(_xlfn.XLOOKUP(TRIM(G13), Sheet1!$C:$C, Sheet1!$E:$E), "")
A14: Chandra Shekar Sarap | B14: Vice President Research & Development - Data Science | C14: Valtep | D14: 0.8 | E14: multiscale modelling | F14: Graphene | G14: https://www.linkedin.com/in/chandra-shekar-sarap-85a89145 | H14: Hyderabad | I14: Saudi Arabia | J14: India | L14: =IFERROR(_xlfn.XLOOKUP(TRIM(G14), Sheet1!$C:$C, Sheet1!$E:$E), "")
A15: Janapriya Jeganathan | B15: Operations Analyst | C15: Greensky® | D15: 1+ | E15: SQL | F15: C (Programming Language) | G15: https://www.linkedin.com/in/janapriya-jeganathan | H15: Austin | I15: Texas | J15: United States | L15: =IFERROR(_xlfn.XLOOKUP(TRIM(G15), Sheet1!$C:$C, Sheet1!$E:$E), "")
A16: Sravya Jahagirdar | B16: Technical Product Owner | C16: Autozone | D16: 1 | E16: WMS | F16: Supply Chain Operations | G16: https://www.linkedin.com/in/sravyajahagirdar | H16: New York City Metropolitan Area | I16: New York | J16: United States | L16: =IFERROR(_xlfn.XLOOKUP(TRIM(G16), Sheet1!$C:$C, Sheet1!$E:$E), "")
A17: Damien Gombert | B17: Quality Assurance Engineer | C17: Bently Nevada, A Baker Hughes Business | D17: 6+ | E17: Tableau | F17: Quality Management | G17: https://www.linkedin.com/in/damiengombert | H17: Greater Reno Area | I17: vijay72prince@gmail.com | J17: United States | L17: =IFERROR(_xlfn.XLOOKUP(TRIM(G17), Sheet1!$C:$C, Sheet1!$E:$E), "")
A18: Richard Troscianecki | B18: Real Estate Agent | C18: Century 21 Select Group | D18: 4+ | E18: EMC Documentum | F18: Pega PRPC | G18: https://www.linkedin.com/in/richardtroscianecki | H18: Gouldsboro | I18: North Carolina | J18: United States | L18: =IFERROR(_xlfn.XLOOKUP(TRIM(G18), Sheet1!$C:$C, Sheet1!$E:$E), "")
A19: Jessima Aiman | B19: Manager - Business Development | C19: Oneorigin | D19: 1+ | E19: Business Development | F19: Management | G19: https://www.linkedin.com/in/jessima-aiman | H19: Scottsdale | I19: California | J19: United States | L19: =IFERROR(_xlfn.XLOOKUP(TRIM(G19), Sheet1!$C:$C, Sheet1!$E:$E), "")
A20: Aditya Pujari | B20: Sr consultant | C20: Ey | D20: 0.4 | E20: Timelines | F20: Scorecard | G20: https://www.linkedin.com/in/adityapujari777 | H20: Mumbai | I20: Michigan | J20: India | L20: =IFERROR(_xlfn.XLOOKUP(TRIM(G20), Sheet1!$C:$C, Sheet1!$E:$E), "")
A21: Md Ahmed Ali | B21: Sr. Bench Sales Recruiter | C21: Career Soft Solutions Inc | D21: 1+ | E21: Screening Resumes | G21: https://www.linkedin.com/in/mohammed-recruiter | H21: New York City Metropolitan Area | I21: New York | J21: United States | L21: =IFERROR(_xlfn.XLOOKUP(TRIM(G21), Sheet1!$C:$C, Sheet1!$E:$E), "")
A22: Sangeetha Jayakrishnan | B22: Practice Manager | D22: 2+ | E22: Records Management | F22: leadership | G22: https://www.linkedin.com/in/sangeethajayakrishnan | H22: Livermore | I22: Haryana | J22: United States | L22: =IFERROR(_xlfn.XLOOKUP(TRIM(G22), Sheet1!$C:$C, Sheet1!$E:$E), "")
A23: Ganesan V | B23: Performance Marketing Consultant | D23: 0.3 | E23: YouTube | F23: Google Ads | G23: https://www.linkedin.com/in/ganesan-v | H23: Tamil Nadu | I23: India | L23: =IFERROR(_xlfn.XLOOKUP(TRIM(G23), Sheet1!$C:$C, Sheet1!$E:$E), "")
A24: Madhumitha Rajesh | B24: User Experience Intern | C24: Playerapp | D24: 0.3 | E24: AI-Powered Research Tools | F24: Data Analysis | G24: https://www.linkedin.com/in/madhumitha-rajesh-76078018a | H24: Greater Seattle Area | I24: Washington | J24: United States | L24: =IFERROR(_xlfn.XLOOKUP(TRIM(G24), Sheet1!$C:$C, Sheet1!$E:$E), "")
A25: Amit Trivedi | B25: Staffing Consultant | C25: Confidential | D25: 1+ | E25: Staffing Industry | F25: Sales | G25: https://www.linkedin.com/in/amit-trivedi-9aa42b14 | H25: India | I25: India | J25: United States | L25: =IFERROR(_xlfn.XLOOKUP(TRIM(G25), Sheet1!$C:$C, Sheet1!$E:$E), "")
A26: MANOJ BAKSHI | B26: PRINTING | G26: https://www.linkedin.com/in/manoj-bakshi-24178a1b | H26: Noida | I26: Telangana | J26: India | L26: =IFERROR(_xlfn.XLOOKUP(TRIM(G26), Sheet1!$C:$C, Sheet1!$E:$E), "")
A27: Anson Mathew | B27: Team Lead | D27: 9+ | E27: SDLC | F27: XML | G27: https://www.linkedin.com/in/anson-mathew-a8ab4465 | H27: Olathe | I27: Missouri | J27: United States | L27: =IFERROR(_xlfn.XLOOKUP(TRIM(G27), Sheet1!$C:$C, Sheet1!$E:$E), "")
A28: Dinesh Kumar Rajendran | B28: Director- Head of Sales | C28: Highbrow Technology Inc | D28: 2+ | E28: Business Integration | F28: Partnership & Relationship Building | G28: https://www.linkedin.com/in/dinesh-kumar-rajendran | H28: Morrisville | I28: Bihar | J28: United States | L28: =IFERROR(_xlfn.XLOOKUP(TRIM(G28), Sheet1!$C:$C, Sheet1!$E:$E), "")
A29: Swetha Ragothaman | B29: Program Manager | C29: Zero Rideshare | D29: 1+ | E29: Zoho CRM | F29: Functional Testing | G29: https://www.linkedin.com/in/swetha-ragothaman | H29: San Francisco Bay Area | I29: California | J29: United States | L29: =IFERROR(_xlfn.XLOOKUP(TRIM(G29), Sheet1!$C:$C, Sheet1!$E:$E), "")
A30: Calvin Dcosta | B30: NetSuite Functional Consultant - Configurations | C30: Zenardy | D30: 1+ | E30: NetSuite ERP Configurations & Customization | F30: Data Visualization & Reporting | G30: https://www.linkedin.com/in/calvin-dcosta | H30: Mumbai | I30: Michigan | J30: India | L30: =IFERROR(_xlfn.XLOOKUP(TRIM(G30), Sheet1!$C:$C, Sheet1!$E:$E), "")
A31: Tamilarasan S | B31: Suppy Chain and Delivery Manager | C31: Natwest Group | D31: 2+ | E31: Microsoft Copilot Studio | F31: Agile Methodologies | G31: https://www.linkedin.com/in/tamizh1 | H31: Chennai | I31: India | J31: India | L31: =IFERROR(_xlfn.XLOOKUP(TRIM(G31), Sheet1!$C:$C, Sheet1!$E:$E), "")
A32: Amol Khugshal | B32: Senior Product Manager | C32: Miniclip | D32: 0.6 | E32: Monetization | F32: User Research | G32: https://www.linkedin.com/in/amol-khugshal | H32: Portugal | L32: =IFERROR(_xlfn.XLOOKUP(TRIM(G32), Sheet1!$C:$C, Sheet1!$E:$E), "")
A33: Elma Mathew | B33: Registered Nurse | C33: Pine Valley Center For Rehabilitation | D33: 1+ | E33: Data Analysis | F33: Customer Service | G33: https://www.linkedin.com/in/elma-mathew-3970361b9 | H33: West Haverstraw | I33: Karnataka | J33: United States | L33: =IFERROR(_xlfn.XLOOKUP(TRIM(G33), Sheet1!$C:$C, Sheet1!$E:$E), "")
A34: Prasanna Balachandran | B34: Technical Delivery Manager | C34: Ey | D34: 8+ | E34: Fieldglass | F34: Product Owner | G34: https://www.linkedin.com/in/prasanna-balachandran-cloud-enthusiast | H34: Metro Jacksonville | I34: Prasanna2567@gmail.com | L34: =IFERROR(_xlfn.XLOOKUP(TRIM(G34), Sheet1!$C:$C, Sheet1!$E:$E), "")
A35: veeramani subramaniam | B35: Manager | C35: Cognizant | D35: 3+ | E35: PL/SQL | F35: Oracle | G35: https://www.linkedin.com/in/veeramani-subramaniam-9271a77 | H35: Raleigh-Durham-Chapel Hill Area | I35: North Carolina | L35: =IFERROR(_xlfn.XLOOKUP(TRIM(G35), Sheet1!$C:$C, Sheet1!$E:$E), "")
A36: Anshul . | B36: AVP-Operations | C36: Echelon Edge | D36: 0.8 | E36: Sales Processes | F36: Sales | G36: https://www.linkedin.com/in/anshul-90a80988 | H36: Gurugram | I36: Pakistan | J36: India | L36: =IFERROR(_xlfn.XLOOKUP(TRIM(G36), Sheet1!$C:$C, Sheet1!$E:$E), "")
A37: CHIBWE CHUNGU | B37: Americas Operations Lead Vegetables Seeds Development | C37: Syngenta | D37: 1+ | E37: Speaking | F37: Facilitation | G37: https://www.linkedin.com/in/chibwe-chungu1997 | H37: Galt | I37: Haryana | J37: United States | L37: =IFERROR(_xlfn.XLOOKUP(TRIM(G37), Sheet1!$C:$C, Sheet1!$E:$E), "")
A38: Ranganath P. | B38: Validation Lead | C38: Genentech | D38: 11+ | E38: U.S. Title 21 CFR Part 11 Regulation | F38: Change Control | G38: https://www.linkedin.com/in/ranganath-p-a41391149 | H38: Fremont | I38: Haryana | J38: United States | L38: =IFERROR(_xlfn.XLOOKUP(TRIM(G38), Sheet1!$C:$C, Sheet1!$E:$E), "")
A39: Keerthana Nagula | B39: Business Intelligence Engineer | C39: Impetus | D39: 1+ | E39: Requirements Analysis | F39: Business Requirements | G39: https://www.linkedin.com/in/keerthana-nagula | H39: Bengaluru | I39: Bahrain | J39: India | L39: =IFERROR(_xlfn.XLOOKUP(TRIM(G39), Sheet1!$C:$C, Sheet1!$E:$E), "")
A40: Madhu Gupta | B40: Personal Branding & Ghostwriting | D40: 4+ | E40: Social Media | F40: Marketing Strategy | G40: https://www.linkedin.com/in/madhudigitalmarketer | H40: Mumbai | I40: Michigan | J40: India | L40: =IFERROR(_xlfn.XLOOKUP(TRIM(G40), Sheet1!$C:$C, Sheet1!$E:$E), "")
...

Sheet Sheet1
A1: Designation | B1: Location | C1: Linkedin Url | D1: raw text | E1: Email
A2: Instrumentation Design Engineer | B2: Haryana | C2: https://www.linkedin.com/in/eashangsingh | D2: Eashan Singh - New York, New York, United States .singh1@gmail.com. I look forward to speaking with you! · Experience ... Software Engineering Intern. Google. May 2023 - Aug 2023 4 ... | E2: .singh1@gmail.com
A3: Chat Support Executive | B3: Aurangabad | C3: https://www.linkedin.com/in/ananyayadav | D3: Ananya Yadav - New York City Metropolitan Area ... chat about data, innovation, or books, let's connect! Reach me at 06ananyayadav06@gmail.com ... executives. Optimizing Supply Chain Operations with Data ... | E3: 06ananyayadav06@gmail.com
A4: Civil Quality Engineer | B4: Meerut | C4: https://www.linkedin.com/in/hritik-garg-249905163/ | D4: Hritik Garg - Associate SDET - Taazaa Inc Version control wiz using GitHub for collaborative coding. Eager to connect and grow. Let's chat: 13hritik@gmail.com or right here on LinkedIn. | E4: 13hritik@gmail.com
A5: Email Support Executive | B5: Jodhpur | C5: https://www.linkedin.com/in/jayeshkumarpatel-41839621 | D5: JAYESH KUMAR PATEL - General Manager ... email me at 1972.patel@gmail.com · Experience: General Manager at Joshi Technologeis Intl Inc · Education: B.Sc. from J&J College of Science-Gujarat ... | E5: 1972.patel@gmail.com
A6: Email Support Executive | B6: Agra | C6: https://www.linkedin.com/in/kazhall | D6: Karen Hall - Mindfulness Retreat Leader - Way of ... ... email me at 1kazhall@gmail.com. Articles by Karen. Kerala, January 2024 ... Business Support Manager 0121 466 7544. Email: eileen.brennan@bhamcommunity ... | E6: 1kazhall@gmail.com
A7: Light Vehicle Driver | B7: Andhra Pradesh | C7: https://www.linkedin.com/in/troy-hanson- | D7: Troy Hanson - Race Team Manager - Principle Engineer ... Automotive Engineering ▻ Contact: 1tj.hanson@gmail.com · Experience: Honda Performance Development · Education: Madison Area Technical College · Location ... | E7: 1tj.hanson@gmail.com
A8: Commercial Executive | B8: Rajkot | C8: https://www.linkedin.com/in/themehulpatil | D8: Mehul Patil - Sr. Executive Digital Marketing - KP Group ✉️ Email me at mehulpatil@273@gmail.com. Services. Blogging · Market Research · Content Strategy · Digital Marketing · Content Marketing · Search Engine ... | E8: 273@gmail.com
A9: Sales Representative | B9: Vadodara | C9: https://www.linkedin.com/in/jamespoole0in0raleighnc | D9: James L Poole - Duke Energy Corporation 400emerson@gmail.com / 919 621-0891 (mobile) Technical Professional with proven… · Experience: Duke Energy Corporation · Education: North Carolina State ... | E9: 400emerson@gmail.com
A10: Document Verification Executive | B10: Andhra Pradesh | C10: https://www.linkedin.com/in/yifanyang25 | D10: Yifan Yang - Salesforce Functional Analyst - Sysco • Handled DHL's Sanity Check Tool to check and correct all the potential errors before the quotation submission ... Credential ID 7yyang7@gmail.com. See ... | E10: 7yyang7@gmail.com
A11: Technician | B11: Andhra Pradesh | C11: https://www.linkedin.com/in/carlene-artist-a384a776 | D11: Carlene Artist - District Supervisor - Survey.com We are currently taking applications for students,simply send us a email to 8counts2dance@gmail.com and we will get a application form to you as soon as ... | E11: 8counts2dance@gmail.com
A12: Industrial safety officer | B12: Andhra Pradesh | C12: https://www.linkedin.com/in/a-lake-wooten | D12: Andrew Lake Wooten - Purdue University College of ... a.lake.wooten@gmail.com • 12 years in radiopharmaceuticals and medical isotopes with… · Experience: Purdue University College of Pharmacy · Education: ... | E12: a.lake.wooten@gmail.com
... A2434: Courier Executive | B2434: Bihar | C2434: https://www.linkedin.com/in/zubinkhan1 | D2434: Zubin Khan, MS - Sr. Health Informaticist ... leadership roles focused on leveraging informatics to drive strategic transformation and data-driven decision-making. Connect with me at zubink24@gmail.com ... | E2434: zubink24@gmail.com
